Workbook

Sheet Draft Board
A1: f
D2: Brady Gaga | I2: Bishop Sycamore | N2: Amity Island Sharks | S2: Bojangles Pornstars | X2: Foxboro Forever | AC2: Wiesbaden Phantoms | AH2: Pep's Band | AM2: Zeugen Ray Lewis | AR2: Frankfurt Packers | AW2: Steelersnation 7 | BB2: E-Town Elephants | BG2: The 49vengers | BL2: Randy Moss LoB Juenger | BQ2: Johnny Manziel and Friends | BV2: BearD | CA2: K-Town Devils | CF2: Thunder Ducks | CK2: the Boys | CP2: Fighting Farmers | CU2: Broken Bembels ULB
B4: 1. Runde | D4: Christian McCaffrey | I4: Tyreek Hill | N4: CeeDee Lamb | S4: Ja'Marr Chase | X4: Breece Hall | AC4: Travis Kelce | AH4: Bijan Robinson | AM4: Jahmyr Gibbs | AR4: Amon-Ra St. Brown | AW4: Derrick Henry | BB4: Josh Jacobs | BG4: Justin Jefferson | BL4: A.J. Brown | BQ4: Josh Allen | BV4: Garrett Wilson | CA4: Saquon Barkley | CF4: Jonathan Taylor | CK4: Kyren Williams | CP4: Travis Etienne Jr. | CU4: De'Von Achane
D5: =IF(D4="","",VLOOKUP(D4,'[1]All Player'!$A$2:$D$517,2,FALSE)) -> SF | E5: - | F5: =IF(D4="","",VLOOKUP(D4,'[1]All Player'!$A$2:$D$517,4,FALSE)) -> RB | G5: =LEFT(B4,1)+0.01 -> 1.01 | I5: =IF(I4="","",VLOOKUP(I4,'[1]All Player'!$A$2:$D$517,2,FALSE)) -> MIA | J5: - | K5: =IF(I4="","",VLOOKUP(I4,'[1]All Player'!$A$2:$D$517,4,FALSE)) -> WR | L5: =G5+0.01 -> 1.02 | N5: =IF(N4="","",VLOOKUP(N4,'[1]All Player'!$A$2:$D$517,2,FALSE)) -> DAL | O5: - | P5: =IF(N4="","",VLOOKUP(N4,'[1]All Player'!$A$2:$D$517,4,FALSE)) -> WR | Q5: =L5+0.01 -> 1.03 | S5: =IF(S4="","",VLOOKUP(S4,'[1]All Player'!$A$2:$D$517,2,FALSE)) -> CIN | T5: - | U5: =IF(S4="","",VLOOKUP(S4,'[1]All Player'!$A$2:$D$517,4,FALSE)) -> WR | V5: =Q5+0.01 -> 1.04 | X5: =IF(X4="","",VLOOKUP(X4,'[1]All Player'!$A$2:$D$517,2,FALSE)) -> NYJ | Y5: - | Z5: =IF(X4="","",VLOOKUP(X4,'[1]All Player'!$A$2:$D$517,4,FALSE)) -> RB | AA5: =V5+0.01 -> 1.05 | AC5: =IF(AC4="","",VLOOKUP(AC4,'[1]All Player'!$A$2:$D$517,2,FALSE)) -> KC | AD5: - | AE5: =IF(AC4="","",VLOOKUP(AC4,'[1]All Player'!$A$2:$D$517,4,FALSE)) -> TE | AF5: =AA5+0.01 -> 1.06 | AH5: =IF(AH4="","",VLOOKUP(AH4,'[1]All Player'!$A$2:$D$517,2,FALSE)) -> ATL | AI5: - | AJ5: =IF(AH4="","",VLOOKUP(AH4,'[1]All Player'!$A$2:$D$517,4,FALSE)) -> RB | AK5: =AF5+0.01 -> 1.07 | AM5: =IF(AM4="","",VLOOKUP(AM4,'[1]All Player'!$A$2:$D$517,2,FALSE)) -> DET | AN5: - | AO5: =IF(AM4="","",VLOOKUP(AM4,'[1]All Player'!$A$2:$D$517,4,FALSE)) -> RB | AP5: =AK5+0.01 -> 1.08 | AR5: =IF(AR4="","",VLOOKUP(AR4,'[1]All Player'!$A$2:$D$517,2,FALSE)) -> DET | AS5: - | AT5: =IF(AR4="","",VLOOKUP(AR4,'[1]All Player'!$A$2:$D$517,4,FALSE)) -> WR | AU5: =AP5+0.01 -> 1.09 | AW5: =IF(AW4="","",VLOOKUP(AW4,'[1]All Player'!$A$2:$D$517,2,FALSE)) -> BAL | AX5: - | AY5: =IF(AW4="","",VLOOKUP(AW4,'[1]All Player'!$A$2:$D$517,4,FALSE)) -> RB | AZ5: =AU5+0.01 -> 1.1 | BB5: =IF(BB4="","",VLOOKUP(BB4,'[1]All Player'!$A$2:$D$517,2,FALSE)) -> GB | BC5: - | BD5: =IF(BB4="","",VLOOKUP(BB4,'[1]All Player'!$A$2:$D$517,4,FALSE)) -> RB | BE5: =AZ5+0.01 -> 1.11 | BG5: =IF(BG4="","",VLOOKUP(BG4,'[1]All Player'!$A$2:$D$517,2,FALSE)) -> MIN | BH5: - | BI5: =IF(BG4="","",VLOOKUP(BG4,'[1]All Player'!$A$2:$D$517,4,FALSE)) -> WR | BJ5: =BE5+0.01 -> 1.12 | BL5: =IF(BL4="","",VLOOKUP(BL4,'[1]All Player'!$A$2:$D$517,2,FALSE)) -> PHI | BM5: - | BN5: =IF(BL4="","",VLOOKUP(BL4,'[1]All Player'!$A$2:$D$517,4,FALSE)) -> WR | BO5: =BJ5+0.01 -> 1.13 | BQ5: =IF(BQ4="","",VLOOKUP(BQ4,'[1]All Player'!$A$2:$D$517,2,FALSE)) -> BUF | BR5: - | BS5: =IF(BQ4="","",VLOOKUP(BQ4,'[1]All Player'!$A$2:$D$517,4,FALSE)) -> QB | BT5: =BO5+0.01 -> 1.14 | BV5: =IF(BV4="","",VLOOKUP(BV4,'[1]All Player'!$A$2:$D$517,2,FALSE)) -> NYJ | BW5: - | BX5: =IF(BV4="","",VLOOKUP(BV4,'[1]All Player'!$A$2:$D$517,4,FALSE)) -> WR | BY5: =BT5+0.01 -> 1.15 | CA5: =IF(CA4="","",VLOOKUP(CA4,'[1]All Player'!$A$2:$D$517,2,FALSE)) -> PHI | CB5: - | CC5: =IF(CA4="","",VLOOKUP(CA4,'[1]All Player'!$A$2:$D$517,4,FALSE)) -> RB | CD5: =BY5+0.01 -> 1.16 | CF5: =IF(CF4="","",VLOOKUP(CF4,'[1]All Player'!$A$2:$D$517,2,FALSE)) -> IND | CG5: - | CH5: =IF(CF4="","",VLOOKUP(CF4,'[1]All Player'!$A$2:$D$517,4,FALSE)) -> RB | CI5: =CD5+0.01 -> 1.17 | CK5: =IF(CK4="","",VLOOKUP(CK4,'[1]All Player'!$A$2:$D$517,2,FALSE)) -> LAR | CL5: - | CM5: =IF(CK4="","",VLOOKUP(CK4,'[1]All Player'!$A$2:$D$517,4,FALSE)) -> RB | CN5: =CI5+0.01 -> 1.18 | CP5: =IF(CP4="","",VLOOKUP(CP4,'[1]All Player'!$A$2:$D$517,2,FALSE)) -> JAC | CQ5: - | CR5: =IF(CP4="","",VLOOKUP(CP4,'[1]All Player'!$A$2:$D$517,4,FALSE)) -> RB | CS5: =CN5+0.01 -> 1.19 | CU5: =IF(CU4="","",VLOOKUP(CU4,'[1]All Player'!$A$2:$D$517,2,FALSE)) -> MIA | CV5: - | CW5: =IF(CU4="","",VLOOKUP(CU4,'[1]All Player'!$A$2:$D$517,4,FALSE)) -> RB | CX5: =CS5+0.01 -> 1.2
B7: 2. Runde | D7: Lamar Jackson | I7: Aaron Jones | N7: Jaylen Waddle | S7: DK Metcalf | X7: Michael Pittman Jr. | AC7: Kenneth Walker III | AH7: Joe Mixon | AM7: James Cook | AR7: James Conner | AW7: Deebo Samuel Sr. | BB7: Sam LaPorta | BG7: Jalen Hurts | BL7: Alvin Kamara | BQ7: Rachaad White | BV7: Chris Olave | CA7: Marvin Harrison Jr. | CF7: Isiah Pacheco | CK7: Brandon Aiyuk | CP7: Stefon Diggs | CU7: Puka Nacua
D8: =IF(D7="","",VLOOKUP(D7,'[1]All Player'!$A$2:$D$517,2,FALSE)) -> BAL | E8: - | F8: =IF(D7="","",VLOOKUP(D7,'[1]All Player'!$A$2:$D$517,4,FALSE)) -> QB | G8: =LEFT(B7,1)+0.2 -> 2.2 | I8: =IF(I7="","",VLOOKUP(I7,'[1]All Player'!$A$2:$D$517,2,FALSE)) -> MIN | J8: - | K8: =IF(I7="","",VLOOKUP(I7,'[1]All Player'!$A$2:$D$517,4,FALSE)) -> RB | L8: =G8-0.01 -> 2.19 | N8: =IF(N7="","",VLOOKUP(N7,'[1]All Player'!$A$2:$D$517,2,FALSE)) -> MIA | O8: - | P8: =IF(N7="","",VLOOKUP(N7,'[1]All Player'!$A$2:$D$517,4,FALSE)) -> WR | Q8: =L8-0.01 -> 2.18 | S8: =IF(S7="","",VLOOKUP(S7,'[1]All Player'!$A$2:$D$517,2,FALSE)) -> SEA | T8: - | U8: =IF(S7="","",VLOOKUP(S7,'[1]All Player'!$A$2:$D$517,4,FALSE)) -> WR | V8: =Q8-0.01 -> 2.17 | X8: =IF(X7="","",VLOOKUP(X7,'[1]All Player'!$A$2:$D$517,2,FALSE)) -> IND | Y8: - | Z8: =IF(X7="","",VLOOKUP(X7,'[1]All Player'!$A$2:$D$517,4,FALSE)) -> WR | AA8: =V8-0.01 -> 2.16 | AC8: =IF(AC7="","",VLOOKUP(AC7,'[1]All Player'!$A$2:$D$517,2,FALSE)) -> SEA | AD8: - | AE8: =IF(AC7="","",VLOOKUP(AC7,'[1]All Player'!$A$2:$D$517,4,FALSE)) -> RB | AF8: =AA8-0.01 -> 2.15 | AH8: =IF(AH7="","",VLOOKUP(AH7,'[1]All Player'!$A$2:$D$517,2,FALSE)) -> HOU | AI8: - | AJ8: =IF(AH7="","",VLOOKUP(AH7,'[1]All Player'!$A$2:$D$517,4,FALSE)) -> RB | AK8: =AF8-0.01 -> 2.14 | AM8: =IF(AM7="","",VLOOKUP(AM7,'[1]All Player'!$A$2:$D$517,2,FALSE)) -> BUF | AN8: - | AO8: =IF(AM7="","",VLOOKUP(AM7,'[1]All Player'!$A$2:$D$517,4,FALSE)) -> RB | AP8: =AK8-0.01 -> 2.13 | AR8: =IF(AR7="","",VLOOKUP(AR7,'[1]All Player'!$A$2:$D$517,2,FALSE)) -> ARI | AS8: - | AT8: =IF(AR7="","",VLOOKUP(AR7,'[1]All Player'!$A$2:$D$517,4,FALSE)) -> RB | AU8: =AP8-0.01 -> 2.12 | AW8: =IF(AW7="","",VLOOKUP(AW7,'[1]All Player'!$A$2:$D$517,2,FALSE)) -> SF | AX8: - | AY8: =IF(AW7="","",VLOOKUP(AW7,'[1]All Player'!$A$2:$D$517,4,FALSE)) -> WR | AZ8: =AU8-0.01 -> 2.11 | BB8: =IF(BB7="","",VLOOKUP(BB7,'[1]All Player'!$A$2:$D$517,2,FALSE)) -> DET | BC8: - | BD8: =IF(BB7="","",VLOOKUP(BB7,'[1]All Player'!$A$2:$D$517,4,FALSE)) -> TE | BE8: =AZ8-0.01 -> 2.1 | BG8: =IF(BG7="","",VLOOKUP(BG7,'[1]All Player'!$A$2:$D$517,2,FALSE)) -> PHI | BH8: - | BI8: =IF(BG7="","",VLOOKUP(BG7,'[1]All Player'!$A$2:$D$517,4,FALSE)) -> QB | BJ8: =BE8-0.01 -> 2.09 | BL8: =IF(BL7="","",VLOOKUP(BL7,'[1]All Player'!$A$2:$D$517,2,FALSE)) -> NO | BM8: - | BN8: =IF(BL7="","",VLOOKUP(BL7,'[1]All Player'!$A$2:$D$517,4,FALSE)) -> RB | BO8: =BJ8-0.01 -> 2.08 | BQ8: =IF(BQ7="","",VLOOKUP(BQ7,'[1]All Player'!$A$2:$D$517,2,FALSE)) -> TB | BR8: - | BS8: =IF(BQ7="","",VLOOKUP(BQ7,'[1]All Player'!$A$2:$D$517,4,FALSE)) -> RB | BT8: =BO8-0.01 -> 2.07 | BV8: =IF(BV7="","",VLOOKUP(BV7,'[1]All Player'!$A$2:$D$517,2,FALSE)) -> NO | BW8: - | BX8: =IF(BV7="","",VLOOKUP(BV7,'[1]All Player'!$A$2:$D$517,4,FALSE)) -> WR | BY8: =BT8-0.01 -> 2.06 | CA8: =IF(CA7="","",VLOOKUP(CA7,'[1]All Player'!$A$2:$D$517,2,FALSE)) -> ARI | CB8: - | CC8: =IF(CA7="","",VLOOKUP(CA7,'[1]All Player'!$A$2:$D$517,4,FALSE)) -> WR | CD8: =BY8-0.01 -> 2.05 | CF8: =IF(CF7="","",VLOOKUP(CF7,'[1]All Player'!$A$2:$D$517,2,FALSE)) -> KC | CG8: - | CH8: =IF(CF7="","",VLOOKUP(CF7,'[1]All Player'!$A$2:$D$517,4,FALSE)) -> RB | CI8: =CD8-0.01 -> 2.04 | CK8: =IF(CK7="","",VLOOKUP(CK7,'[1]All Player'!$A$2:$D$517,2,FALSE)) -> SF | CL8: - | CM8: =IF(CK7="","",VLOOKUP(CK7,'[1]All Player'!$A$2:$D$517,4,FALSE)) -> WR | CN8: =CI8-0.01 -> 2.03 | CP8: =IF(CP7="","",VLOOKUP(CP7,'[1]All Player'!$A$2:$D$517,2,FALSE)) -> HOU | CQ8: - | CR8: =IF(CP7="","",VLOOKUP(CP7,'[1]All Player'!$A$2:$D$517,4,FALSE)) -> WR | CS8: =CN8-0.01 -> 2.02 | CU8: =IF(CU7="","",VLOOKUP(CU7,'[1]All Player'!$A$2:$D$517,2,FALSE)) -> LAR | CV8: - | CW8: =IF(CU7="","",VLOOKUP(CU7,'[1]All Player'!$A$2:$D$517,4,FALSE)) -> WR | CX8: =CS8-0.01 -> 2.01
B10: 3. Runde | D10: Mike Evans | I10: Davante Adams | N10: David Montgomery | S10: Nick Chubb | X10: Rhamondre Stevenson | AC10: Drake London | AH10: D'Andre Swift | AM10: Cooper Kupp | AR10: Zamir White | AW10: Najee Harris | BB10: Tony Pollard | BG10: Mark Andrews | BL10: DJ Moore | BQ10: Nico Collins | BV10: Javonte Williams | CA10: Amari Cooper | CF10: DeVonta Smith | CK10: Tee Higgins | CP10: Patrick Mahomes II | CU10: Zay FLowers
D11: =IF(D10="","",VLOOKUP(D10,'[1]All Player'!$A$2:$D$517,2,FALSE)) -> TB | E11: - | F11: =IF(D10="","",VLOOKUP(D10,'[1]All Player'!$A$2:$D$517,4,FALSE)) -> WR | G11: =LEFT(B10,1)+0.01 -> 3.01 | I11: =IF(I10="","",VLOOKUP(I10,'[1]All Player'!$A$2:$D$517,2,FALSE)) -> LV | J11: - | K11: =IF(I10="","",VLOOKUP(I10,'[1]All Player'!$A$2:$D$517,4,FALSE)) -> WR | L11: =G11+0.01 -> 3.02 | N11: =IF(N10="","",VLOOKUP(N10,'[1]All Player'!$A$2:$D$517,2,FALSE)) -> DET | O11: - | P11: =IF(N10="","",VLOOKUP(N10,'[1]All Player'!$A$2:$D$517,4,FALSE)) -> RB | Q11: =L11+0.01 -> 3.03 | S11: =IF(S10="","",VLOOKUP(S10,'[1]All Player'!$A$2:$D$517,2,FALSE)) -> CLE | T11: - | U11: =IF(S10="","",VLOOKUP(S10,'[1]All Player'!$A$2:$D$517,4,FALSE)) -> RB | V11: =Q11+0.01 -> 3.04 | X11: =IF(X10="","",VLOOKUP(X10,'[1]All Player'!$A$2:$D$517,2,FALSE)) -> NE | Y11: - | Z11: =IF(X10="","",VLOOKUP(X10,'[1]All Player'!$A$2:$D$517,4,FALSE)) -> RB | AA11: =V11+0.01 -> 3.05 | AC11: =IF(AC10="","",VLOOKUP(AC10,'[1]All Player'!$A$2:$D$517,2,FALSE)) -> ATL | AD11: - | AE11: =IF(AC10="","",VLOOKUP(AC10,'[1]All Player'!$A$2:$D$517,4,FALSE)) -> WR | AF11: =AA11+0.01 -> 3.06 | AH11: =IF(AH10="","",VLOOKUP(AH10,'[1]All Player'!$A$2:$D$517,2,FALSE)) -> CHI | AI11: - | AJ11: =IF(AH10="","",VLOOKUP(AH10,'[1]All Player'!$A$2:$D$517,4,FALSE)) -> RB | AK11: =AF11+0.01 -> 3.07 | AM11: =IF(AM10="","",VLOOKUP(AM10,'[1]All Player'!$A$2:$D$517,2,FALSE)) -> LAR | AN11: - | AO11: =IF(AM10="","",VLOOKUP(AM10,'[1]All Player'!$A$2:$D$517,4,FALSE)) -> WR | AP11: =AK11+0.01 -> 3.08 | AR11: =IF(AR10="","",VLOOKUP(AR10,'[1]All Player'!$A$2:$D$517,2,FALSE)) -> LV | AS11: - | AT11: =IF(AR10="","",VLOOKUP(AR10,'[1]All Player'!$A$2:$D$517,4,FALSE)) -> RB | AU11: =AP11+0.01 -> 3.09 | AW11: =IF(AW10="","",VLOOKUP(AW10,'[1]All Player'!$A$2:$D$517,2,FALSE)) -> PIT | AX11: - | AY11: =IF(AW10="","",VLOOKUP(AW10,'[1]All Player'!$A$2:$D$517,4,FALSE)) -> RB | AZ11: =AU11+0.01 -> 3.1 | BB11: =IF(BB10="","",VLOOKUP(BB10,'[1]All Player'!$A$2:$D$517,2,FALSE)) -> TEN | BC11: - | BD11: =IF(BB10="","",VLOOKUP(BB10,'[1]All Player'!$A$2:$D$517,4,FALSE)) -> RB | BE11: =AZ11+0.01 -> 3.11 | BG11: =IF(BG10="","",VLOOKUP(BG10,'[1]All Player'!$A$2:$D$517,2,FALSE)) -> BAL | BH11: - | BI11: =IF(BG10="","",VLOOKUP(BG10,'[1]All Player'!$A$2:$D$517,4,FALSE)) -> TE | BJ11: =BE11+0.01 -> 3.12 | BL11: =IF(BL10="","",VLOOKUP(BL10,'[1]All Player'!$A$2:$D$517,2,FALSE)) -> CHI | BM11: - | BN11: =IF(BL10="","",VLOOKUP(BL10,'[1]All Player'!$A$2:$D$517,4,FALSE)) -> WR | BO11: =BJ11+0.01 -> 3.13 | BQ11: =IF(BQ10="","",VLOOKUP(BQ10,'[1]All Player'!$A$2:$D$517,2,FALSE)) -> HOU | BR11: - | BS11: =IF(BQ10="","",VLOOKUP(BQ10,'[1]All Player'!$A$2:$D$517,4,FALSE)) -> WR | BT11: =BO11+0.01 -> 3.14 | BV11: =IF(BV10="","",VLOOKUP(BV10,'[1]All Player'!$A$2:$D$517,2,FALSE)) -> DEN | BW11: - | BX11: =IF(BV10="","",VLOOKUP(BV10,'[1]All Player'!$A$2:$D$517,4,FALSE)) -> RB | BY11: =BT11+0.01 -> 3.15 | CA11: =IF(CA10="","",VLOOKUP(CA10,'[1]All Player'!$A$2:$D$517,2,FALSE)) -> CLE | CB11: - | CC11: =IF(CA10="","",VLOOKUP(CA10,'[1]All Player'!$A$2:$D$517,4,FALSE)) -> WR | CD11: =BY11+0.01 -> 3.16 | CF11: =IF(CF10="","",VLOOKUP(CF10,'[1]All Player'!$A$2:$D$517,2,FALSE)) -> PHI | CG11: - | CH11: =IF(CF10="","",VLOOKUP(CF10,'[1]All Player'!$A$2:$D$517,4,FALSE)) -> WR | CI11: =CD11+0.01 -> 3.17 | CK11: =IF(CK10="","",VLOOKUP(CK10,'[1]All Player'!$A$2:$D$517,2,FALSE)) -> CIN | CL11: - | CM11: =IF(CK10="","",VLOOKUP(CK10,'[1]All Player'!$A$2:$D$517,4,FALSE)) -> WR | CN11: =CI11+0.01 -> 3.18 | CP11: =IF(CP10="","",VLOOKUP(CP10,'[1]All Player'!$A$2:$D$517,2,FALSE)) -> KC | CQ11: - | CR11: =IF(CP10="","",VLOOKUP(CP10,'[1]All Player'!$A$2:$D$517,4,FALSE)) -> QB | CS11: =CN11+0.01 -> 3.19 | CU11: =IF(CU10="","",VLOOKUP(CU10,'[1]All Player'!$A$2:$D$517,2,FALSE)) -> BAL | CV11: - | CW11: =IF(CU10="","",VLOOKUP(CU10,'[1]All Player'!$A$2:$D$517,4,FALSE)) -> WR | CX11: =CS11+0.01 -> 3.2
B13: 4. Runde | D13: Zack Moss | I13: Gus Edwards | N13: Devin Singletary | S13: Austin Ekeler | X13: Rome Odunze | AC13: Ezekiel Elliott | AH13: Tank Dell | AM13: Terry McLaurin | AR13: Malik Nabers | AW13: George Pickens | BB13: Christian Watson | BG13: Brian Robinson Jr. | BL13: George Kittle | BQ13: Dalton Kincaid | BV13: Trey McBride | CA13: Jaylen Warren | CF13: Brock Purdy | CK13: Dak Prescott | CP13: Raheem Mostert | CU13: C.J. Stroud
D14: =IF(D13="","",VLOOKUP(D13,'[1]All Player'!$A$2:$D$517,2,FALSE)) -> CIN | E14: - | F14: =IF(D13="","",VLOOKUP(D13,'[1]All Player'!$A$2:$D$517,4,FALSE)) -> RB | G14: =LEFT(B13,1)+0.2 -> 4.2 | I14: =IF(I13="","",VLOOKUP(I13,'[1]All Player'!$A$2:$D$517,2,FALSE)) -> LAC | J14: - | K14: =IF(I13="","",VLOOKUP(I13,'[1]All Player'!$A$2:$D$517,4,FALSE)) -> RB | L14: =G14-0.01 -> 4.19 | N14: =IF(N13="","",VLOOKUP(N13,'[1]All Player'!$A$2:$D$517,2,FALSE)) -> NYG | O14: - | P14: =IF(N13="","",VLOOKUP(N13,'[1]All Player'!$A$2:$D$517,4,FALSE)) -> RB | Q14: =L14-0.01 -> 4.18 | S14: =IF(S13="","",VLOOKUP(S13,'[1]All Player'!$A$2:$D$517,2,FALSE)) -> WAS | T14: - | U14: =IF(S13="","",VLOOKUP(S13,'[1]All Player'!$A$2:$D$517,4,FALSE)) -> RB | V14: =Q14-0.01 -> 4.17 | X14: =IF(X13="","",VLOOKUP(X13,'[1]All Player'!$A$2:$D$517,2,FALSE)) -> CHI | Y14: - | Z14: =IF(X13="","",VLOOKUP(X13,'[1]All Player'!$A$2:$D$517,4,FALSE)) -> WR | AA14: =V14-0.01 -> 4.16 | AC14: =IF(AC13="","",VLOOKUP(AC13,'[1]All Player'!$A$2:$D$517,2,FALSE)) -> DAL | AD14: - | AE14: =IF(AC13="","",VLOOKUP(AC13,'[1]All Player'!$A$2:$D$517,4,FALSE)) -> RB | AF14: =AA14-0.01 -> 4.15 | AH14: =IF(AH13="","",VLOOKUP(AH13,'[1]All Player'!$A$2:$D$517,2,FALSE)) -> HOU | AI14: - | AJ14: =IF(AH13="","",VLOOKUP(AH13,'[1]All Player'!$A$2:$D$517,4,FALSE)) -> WR | AK14: =AF14-0.01 -> 4.14 | AM14: =IF(AM13="","",VLOOKUP(AM13,'[1]All Player'!$A$2:$D$517,2,FALSE)) -> WAS | AN14: - | AO14: =IF(AM13="","",VLOOKUP(AM13,'[1]All Player'!$A$2:$D$517,4,FALSE)) -> WR | AP14: =AK14-0.01 -> 4.13 | AR14: =IF(AR13="","",VLOOKUP(AR13,'[1]All Player'!$A$2:$D$517,2,FALSE)) -> NYG | AS14: - | AT14: =IF(AR13="","",VLOOKUP(AR13,'[1]All Player'!$A$2:$D$517,4,FALSE)) -> WR | AU14: =AP14-0.01 -> 4.12 | AW14: =IF(AW13="","",VLOOKUP(AW13,'[1]All Player'!$A$2:$D$517,2,FALSE)) -> PIT | AX14: - | AY14: =IF(AW13="","",VLOOKUP(AW13,'[1]All Player'!$A$2:$D$517,4,FALSE)) -> WR | AZ14: =AU14-0.01 -> 4.11 | BB14: =IF(BB13="","",VLOOKUP(BB13,'[1]All Player'!$A$2:$D$517,2,FALSE)) -> GB | BC14: - | BD14: =IF(BB13="","",VLOOKUP(BB13,'[1]All Player'!$A$2:$D$517,4,FALSE)) -> WR | BE14: =AZ14-0.01 -> 4.1 | BG14: =IF(BG13="","",VLOOKUP(BG13,'[1]All Player'!$A$2:$D$517,2,FALSE)) -> WAS | BH14: - | BI14: =IF(BG13="","",VLOOKUP(BG13,'[1]All Player'!$A$2:$D$517,4,FALSE)) -> RB | BJ14: =BE14-0.01 -> 4.09 | BL14: =IF(BL13="","",VLOOKUP(BL13,'[1]All Player'!$A$2:$D$517,2,FALSE)) -> SF | BM14: - | BN14: =IF(BL13="","",VLOOKUP(BL13,'[1]All Player'!$A$2:$D$517,4,FALSE)) -> TE | BO14: =BJ14-0.01 -> 4.08 | BQ14: =IF(BQ13="","",VLOOKUP(BQ13,'[1]All Player'!$A$2:$D$517,2,FALSE)) -> BUF | BR14: - | BS14: =IF(BQ13="","",VLOOKUP(BQ13,'[1]All Player'!$A$2:$D$517,4,FALSE)) -> TE | BT14: =BO14-0.01 -> 4.07 | BV14: =IF(BV13="","",VLOOKUP(BV13,'[1]All Player'!$A$2:$D$517,2,FALSE)) -> ARI | BW14: - | BX14: =IF(BV13="","",VLOOKUP(BV13,'[1]All Player'!$A$2:$D$517,4,FALSE)) -> TE | BY14: =BT14-0.01 -> 4.06 | CA14: =IF(CA13="","",VLOOKUP(CA13,'[1]All Player'!$A$2:$D$517,2,FALSE)) -> PIT | CB14: - | CC14: =IF(CA13="","",VLOOKUP(CA13,'[1]All Player'!$A$2:$D$517,4,FALSE)) -> RB | CD14: =BY14-0.01 -> 4.05 | CF14: =IF(CF13="","",VLOOKUP(CF13,'[1]All Player'!$A$2:$D$517,2,FALSE)) -> SF | CG14: - | CH14: =IF(CF13="","",VLOOKUP(CF13,'[1]All Player'!$A$2:$D$517,4,FALSE)) -> QB | CI14: =CD14-0.01 -> 4.04 | CK14: =IF(CK13="","",VLOOKUP(CK13,'[1]All Player'!$A$2:$D$517,2,FALSE)) -> DAL | CL14: - | CM14: =IF(CK13="","",VLOOKUP(CK13,'[1]All Player'!$A$2:$D$517,4,FALSE)) -> QB | CN14: =CI14-0.01 -> 4.03 | CP14: =IF(CP13="","",VLOOKUP(CP13,'[1]All Player'!$A$2:$D$517,2,FALSE)) -> MIA | CQ14: - | CR14: =IF(CP13="","",VLOOKUP(CP13,'[1]All Player'!$A$2:$D$517,4,FALSE)) -> RB | CS14: =CN14-0.01 -> 4.02 | CU14: =IF(CU13="","",VLOOKUP(CU13,'[1]All Player'!$A$2:$D$517,2,FALSE)) -> HOU | CV14: - | CW14: =IF(CU13="","",VLOOKUP(CU13,'[1]All Player'!$A$2:$D$517,4,FALSE)) -> QB | CX14: =CS14-0.01 -> 4.01
B16: 5. Runde | D16: Rashee Rice | I16: Kyle Pitts | N16: Evan Engram | S16: Jake Ferguson | X16: Jonathon Brooks | AC16: Christian Kirk | AH16: Ladd McConkey | AM16: Anthony Richardson | AR16: Caleb Williams | AW16: David Njoku | BB16: Jordan Love | BG16: Tyjae Spears | BL16: Joe Burrow | BQ16: Justin Tucker | BV16: Chase Brown | CA16: Keenan Allen | CF16: Brock Bowers | CK16: Jerome Ford | CP16: Calvin Ridley | CU16: Chris Godwin
D17: =IF(D16="","",VLOOKUP(D16,'[1]All Player'!$A$2:$D$517,2,FALSE)) -> KC | E17: - | F17: =IF(D16="","",VLOOKUP(D16,'[1]All Player'!$A$2:$D$517,4,FALSE)) -> WR | G17: =LEFT(B16,1)+0.01 -> 5.01 | I17: =IF(I16="","",VLOOKUP(I16,'[1]All Player'!$A$2:$D$517,2,FALSE)) -> ATL | J17: - | K17: =IF(I16="","",VLOOKUP(I16,'[1]All Player'!$A$2:$D$517,4,FALSE)) -> TE | L17: =G17+0.01 -> 5.02 | N17: =IF(N16="","",VLOOKUP(N16,'[1]All Player'!$A$2:$D$517,2,FALSE)) -> JAC | O17: - | P17: =IF(N16="","",VLOOKUP(N16,'[1]All Player'!$A$2:$D$517,4,FALSE)) -> TE | Q17: =L17+0.01 -> 5.03 | S17: =IF(S16="","",VLOOKUP(S16,'[1]All Player'!$A$2:$D$517,2,FALSE)) -> DAL | T17: - | U17: =IF(S16="","",VLOOKUP(S16,'[1]All Player'!$A$2:$D$517,4,FALSE)) -> TE | V17: =Q17+0.01 -> 5.04 | X17: =IF(X16="","",VLOOKUP(X16,'[1]All Player'!$A$2:$D$517,2,FALSE)) -> CAR | Y17: - | Z17: =IF(X16="","",VLOOKUP(X16,'[1]All Player'!$A$2:$D$517,4,FALSE)) -> RB | AA17: =V17+0.01 -> 5.05 | AC17: =IF(AC16="","",VLOOKUP(AC16,'[1]All Player'!$A$2:$D$517,2,FALSE)) -> JAC | AD17: - | AE17: =IF(AC16="","",VLOOKUP(AC16,'[1]All Player'!$A$2:$D$517,4,FALSE)) -> WR | AF17: =AA17+0.01 -> 5.06 | AH17: =IF(AH16="","",VLOOKUP(AH16,'[1]All Player'!$A$2:$D$517,2,FALSE)) -> LAC | AI17: - | AJ17: =IF(AH16="","",VLOOKUP(AH16,'[1]All Player'!$A$2:$D$517,4,FALSE)) -> WR | AK17: =AF17+0.01 -> 5.07 | AM17: =IF(AM16="","",VLOOKUP(AM16,'[1]All Player'!$A$2:$D$517,2,FALSE)) -> IND | AN17: - | AO17: =IF(AM16="","",VLOOKUP(AM16,'[1]All Player'!$A$2:$D$517,4,FALSE)) -> QB | AP17: =AK17+0.01 -> 5.08 | AR17: =IF(AR16="","",VLOOKUP(AR16,'[1]All Player'!$A$2:$D$517,2,FALSE)) -> CHI | AS17: - | AT17: =IF(AR16="","",VLOOKUP(AR16,'[1]All Player'!$A$2:$D$517,4,FALSE)) -> QB | AU17: =AP17+0.01 -> 5.09 | AW17: =IF(AW16="","",VLOOKUP(AW16,'[1]All Player'!$A$2:$D$517,2,FALSE)) -> CLE | AX17: - | AY17: =IF(AW16="","",VLOOKUP(AW16,'[1]All Player'!$A$2:$D$517,4,FALSE)) -> TE | AZ17: =AU17+0.01 -> 5.1 | BB17: =IF(BB16="","",VLOOKUP(BB16,'[1]All Player'!$A$2:$D$517,2,FALSE)) -> GB | BC17: - | BD17: =IF(BB16="","",VLOOKUP(BB16,'[1]All Player'!$A$2:$D$517,4,FALSE)) -> QB | BE17: =AZ17+0.01 -> 5.11 | BG17: =IF(BG16="","",VLOOKUP(BG16,'[1]All Player'!$A$2:$D$517,2,FALSE)) -> TEN | BH17: - | BI17: =IF(BG16="","",VLOOKUP(BG16,'[1]All Player'!$A$2:$D$517,4,FALSE)) -> RB | BJ17: =BE17+0.01 -> 5.12 | BL17: =IF(BL16="","",VLOOKUP(BL16,'[1]All Player'!$A$2:$D$517,2,FALSE)) -> CIN | BM17: - | BN17: =IF(BL16="","",VLOOKUP(BL16,'[1]All Player'!$A$2:$D$517,4,FALSE)) -> QB | BO17: =BJ17+0.01 -> 5.13 | BQ17: =IF(BQ16="","",VLOOKUP(BQ16,'[1]All Player'!$A$2:$D$517,2,FALSE)) -> BAL | BR17: - | BS17: =IF(BQ16="","",VLOOKUP(BQ16,'[1]All Player'!$A$2:$D$517,4,FALSE)) -> K | BT17: =BO17+0.01 -> 5.14 | BV17: =IF(BV16="","",VLOOKUP(BV16,'[1]All Player'!$A$2:$D$517,2,FALSE)) -> CIN | BW17: - | BX17: =IF(BV16="","",VLOOKUP(BV16,'[1]All Player'!$A$2:$D$517,4,FALSE)) -> RB | BY17: =BT17+0.01 -> 5.15 | CA17: =IF(CA16="","",VLOOKUP(CA16,'[1]All Player'!$A$2:$D$517,2,FALSE)) -> CHI | CB17: - | CC17: =IF(CA16="","",VLOOKUP(CA16,'[1]All Player'!$A$2:$D$517,4,FALSE)) -> WR | CD17: =BY17+0.01 -> 5.16 | CF17: =IF(CF16="","",VLOOKUP(CF16,'[1]All Player'!$A$2:$D$517,2,FALSE)) -> LV | CG17: - | CH17: =IF(CF16="","",VLOOKUP(CF16,'[1]All Player'!$A$2:$D$517,4,FALSE)) -> TE | CI17: =CD17+0.01 -> 5.17 | CK17: =IF(CK16="","",VLOOKUP(CK16,'[1]All Player'!$A$2:$D$517,2,FALSE)) -> CLE | CL17: - | CM17: =IF(CK16="","",VLOOKUP(CK16,'[1]All Player'!$A$2:$D$517,4,FALSE)) -> RB | CN17: =CI17+0.01 -> 5.18 | CP17: =IF(CP16="","",VLOOKUP(CP16,'[1]All Player'!$A$2:$D$517,2,FALSE)) -> TEN | CQ17: - | CR17: =IF(CP16="","",VLOOKUP(CP16,'[1]All Player'!$A$2:$D$517,4,FALSE)) -> WR | CS17: =CN17+0.01 -> 5.19 | CU17: =IF(CU16="","",VLOOKUP(CU16,'[1]All Player'!$A$2:$D$517,2,FALSE)) -> TB | CV17: - | CW17: =IF(CU16="","",VLOOKUP(CU16,'[1]All Player'!$A$2:$D$517,4,FALSE)) -> WR | CX17: =CS17+0.01 -> 5.2
B19: 6. Runde | D19: Cole Kmet | I19: Xavier Worthy | N19: Jaleel Mclaughlin | S19: Aaron Rodgers | X19: Jared Goff | AC19: Kirk Cousins | AH19: Tua Tagovailoa | AM19: Luke Musgrave | AR19: Pat Freiermuth | AW19: Chuba Hubbard | BB19: Romeo Doubs | BG19: Diontae Johnson | BL19: Antonio Gibson | BQ19: Baltimore Ravens | BV19: Kyler Murray | CA19: Jayden Daniels | CF19: Zach Charbonnet | CK19: Dalton Schultz | CP19: T.J. Hockenson | CU19: Dallas Goedert
D20: =IF(D19="","",VLOOKUP(D19,'[1]All Player'!$A$2:$D$517,2,FALSE)) -> CHI | E20: - | F20: =IF(D19="","",VLOOKUP(D19,'[1]All Player'!$A$2:$D$517,4,FALSE)) -> TE | G20: =LEFT(B19,1)+0.2 -> 6.2 | I20: =IF(I19="","",VLOOKUP(I19,'[1]All Player'!$A$2:$D$517,2,FALSE)) -> KC | J20: - | K20: =IF(I19="","",VLOOKUP(I19,'[1]All Player'!$A$2:$D$517,4,FALSE)) -> WR | L20: =G20-0.01 -> 6.19 | N20: =IF(N19="","",VLOOKUP(N19,'[1]All Player'!$A$2:$D$517,2,FALSE)) -> DEN | O20: - | P20: =IF(N19="","",VLOOKUP(N19,'[1]All Player'!$A$2:$D$517,4,FALSE)) -> RB | Q20: =L20-0.01 -> 6.18 | S20: =IF(S19="","",VLOOKUP(S19,'[1]All Player'!$A$2:$D$517,2,FALSE)) -> NYJ | T20: - | U20: =IF(S19="","",VLOOKUP(S19,'[1]All Player'!$A$2:$D$517,4,FALSE)) -> QB | V20: =Q20-0.01 -> 6.17 | X20: =IF(X19="","",VLOOKUP(X19,'[1]All Player'!$A$2:$D$517,2,FALSE)) -> DET | Y20: - | Z20: =IF(X19="","",VLOOKUP(X19,'[1]All Player'!$A$2:$D$517,4,FALSE)) -> QB | AA20: =V20-0.01 -> 6.16 | AC20: =IF(AC19="","",VLOOKUP(AC19,'[1]All Player'!$A$2:$D$517,2,FALSE)) -> ATL | AD20: - | AE20: =IF(AC19="","",VLOOKUP(AC19,'[1]All Player'!$A$2:$D$517,4,FALSE)) -> QB | AF20: =AA20-0.01 -> 6.15 | AH20: =IF(AH19="","",VLOOKUP(AH19,'[1]All Player'!$A$2:$D$517,2,FALSE)) -> MIA | AI20: - | AJ20: =IF(AH19="","",VLOOKUP(AH19,'[1]All Player'!$A$2:$D$517,4,FALSE)) -> QB | AK20: =AF20-0.01 -> 6.14 | AM20: =IF(AM19="","",VLOOKUP(AM19,'[1]All Player'!$A$2:$D$517,2,FALSE)) -> GB | AN20: - | AO20: =IF(AM19="","",VLOOKUP(AM19,'[1]All Player'!$A$2:$D$517,4,FALSE)) -> TE | AP20: =AK20-0.01 -> 6.13 | AR20: =IF(AR19="","",VLOOKUP(AR19,'[1]All Player'!$A$2:$D$517,2,FALSE)) -> PIT | AS20: - | AT20: =IF(AR19="","",VLOOKUP(AR19,'[1]All Player'!$A$2:$D$517,4,FALSE)) -> TE | AU20: =AP20-0.01 -> 6.12 | AW20: =IF(AW19="","",VLOOKUP(AW19,'[1]All Player'!$A$2:$D$517,2,FALSE)) -> CAR | AX20: - | AY20: =IF(AW19="","",VLOOKUP(AW19,'[1]All Player'!$A$2:$D$517,4,FALSE)) -> RB | AZ20: =AU20-0.01 -> 6.11 | BB20: =IF(BB19="","",VLOOKUP(BB19,'[1]All Player'!$A$2:$D$517,2,FALSE)) -> GB | BC20: - | BD20: =IF(BB19="","",VLOOKUP(BB19,'[1]All Player'!$A$2:$D$517,4,FALSE)) -> WR | BE20: =AZ20-0.01 -> 6.1 | BG20: =IF(BG19="","",VLOOKUP(BG19,'[1]All Player'!$A$2:$D$517,2,FALSE)) -> CAR | BH20: - | BI20: =IF(BG19="","",VLOOKUP(BG19,'[1]All Player'!$A$2:$D$517,4,FALSE)) -> WR | BJ20: =BE20-0.01 -> 6.09 | BL20: =IF(BL19="","",VLOOKUP(BL19,'[1]All Player'!$A$2:$D$517,2,FALSE)) -> NE | BM20: - | BN20: =IF(BL19="","",VLOOKUP(BL19,'[1]All Player'!$A$2:$D$517,4,FALSE)) -> RB | BO20: =BJ20-0.01 -> 6.08 | BQ20: =IF(BQ19="","",VLOOKUP(BQ19,'[1]All Player'!$A$2:$D$517,2,FALSE)) -> BAL | BR20: - | BS20: =IF(BQ19="","",VLOOKUP(BQ19,'[1]All Player'!$A$2:$D$517,4,FALSE)) -> DEF | BT20: =BO20-0.01 -> 6.07 | BV20: =IF(BV19="","",VLOOKUP(BV19,'[1]All Player'!$A$2:$D$517,2,FALSE)) -> ARI | BW20: - | BX20: =IF(BV19="","",VLOOKUP(BV19,'[1]All Player'!$A$2:$D$517,4,FALSE)) -> QB | BY20: =BT20-0.01 -> 6.06 | CA20: =IF(CA19="","",VLOOKUP(CA19,'[1]All Player'!$A$2:$D$517,2,FALSE)) -> WAS | CB20: - | CC20: =IF(CA19="","",VLOOKUP(CA19,'[1]All Player'!$A$2:$D$517,4,FALSE)) -> QB | CD20: =BY20-0.01 -> 6.05 | CF20: =IF(CF19="","",VLOOKUP(CF19,'[1]All Player'!$A$2:$D$517,2,FALSE)) -> SEA | CG20: - | CH20: =IF(CF19="","",VLOOKUP(CF19,'[1]All Player'!$A$2:$D$517,4,FALSE)) -> RB | CI20: =CD20-0.01 -> 6.04 | CK20: =IF(CK19="","",VLOOKUP(CK19,'[1]All Player'!$A$2:$D$517,2,FALSE)) -> HOU | CL20: - | CM20: =IF(CK19="","",VLOOKUP(CK19,'[1]All Player'!$A$2:$D$517,4,FALSE)) -> TE | CN20: =CI20-0.01 -> 6.03 | CP20: =IF(CP19="","",VLOOKUP(CP19,'[1]All Player'!$A$2:$D$517,2,FALSE)) -> MIN | CQ20: - | CR20: =IF(CP19="","",VLOOKUP(CP19,'[1]All Player'!$A$2:$D$517,4,FALSE)) -> TE | CS20: =CN20-0.01 -> 6.02 | CU20: =IF(CU19="","",VLOOKUP(CU19,'[1]All Player'!$A$2:$D$517,2,FALSE)) -> PHI | CV20: - | CW20: =IF(CU19="","",VLOOKUP(CU19,'[1]All Player'!$A$2:$D$517,4,FALSE)) -> TE | CX20: =CS20-0.01 -> 6.01
B22: 7. Runde | D22: Jayden Reed | I22: Matthew Stafford | N22: Deshaun Watson | S22: Bo Nix | X22: Hunter Henry | AC22: Rico Dowdle | AH22: Hollywood Brown | AM22: Jaxon Smith-Njigba | AR22: Blake Corum | AW22: Russell Wilson | BB22: Tyler Lockett | BG22: Trevor Lawrence | BL22: J.K. Dobbins | BQ22: Trey Benson | BV22: Keon Coleman | CA22: DeAndre Hopkins | CF22: Courtland Sutton | CK22: San Francisco 49ers | CP22: Jordan Addison | CU22: Ty Chandler
D23: =IF(D22="","",VLOOKUP(D22,'[1]All Player'!$A$2:$D$517,2,FALSE)) -> GB | E23: - | F23: =IF(D22="","",VLOOKUP(D22,'[1]All Player'!$A$2:$D$517,4,FALSE)) -> WR | G23: =LEFT(B22,1)+0.01 -> 7.01 | I23: =IF(I22="","",VLOOKUP(I22,'[1]All Player'!$A$2:$D$517,2,FALSE)) -> LAR | J23: - | K23: =IF(I22="","",VLOOKUP(I22,'[1]All Player'!$A$2:$D$517,4,FALSE)) -> QB | L23: =G23+0.01 -> 7.02 | N23: =IF(N22="","",VLOOKUP(N22,'[1]All Player'!$A$2:$D$517,2,FALSE)) -> CLE | O23: - | P23: =IF(N22="","",VLOOKUP(N22,'[1]All Player'!$A$2:$D$517,4,FALSE)) -> QB | Q23: =L23+0.01 -> 7.03 | S23: =IF(S22="","",VLOOKUP(S22,'[1]All Player'!$A$2:$D$517,2,FALSE)) -> DEN | T23: - | U23: =IF(S22="","",VLOOKUP(S22,'[1]All Player'!$A$2:$D$517,4,FALSE)) -> QB | V23: =Q23+0.01 -> 7.04 | X23: =IF(X22="","",VLOOKUP(X22,'[1]All Player'!$A$2:$D$517,2,FALSE)) -> NE | Y23: - | Z23: =IF(X22="","",VLOOKUP(X22,'[1]All Player'!$A$2:$D$517,4,FALSE)) -> TE | AA23: =V23+0.01 -> 7.05 | AC23: =IF(AC22="","",VLOOKUP(AC22,'[1]All Player'!$A$2:$D$517,2,FALSE)) -> DAL | AD23: - | AE23: =IF(AC22="","",VLOOKUP(AC22,'[1]All Player'!$A$2:$D$517,4,FALSE)) -> RB | AF23: =AA23+0.01 -> 7.06 | AH23: =IF(AH22="","",VLOOKUP(AH22,'[1]All Player'!$A$2:$D$517,2,FALSE)) -> KC | AI23: - | AJ23: =IF(AH22="","",VLOOKUP(AH22,'[1]All Player'!$A$2:$D$517,4,FALSE)) -> WR | AK23: =AF23+0.01 -> 7.07 | AM23: =IF(AM22="","",VLOOKUP(AM22,'[1]All Player'!$A$2:$D$517,2,FALSE)) -> SEA | AN23: - | AO23: =IF(AM22="","",VLOOKUP(AM22,'[1]All Player'!$A$2:$D$517,4,FALSE)) -> WR | AP23: =AK23+0.01 -> 7.08 | AR23: =IF(AR22="","",VLOOKUP(AR22,'[1]All Player'!$A$2:$D$517,2,FALSE)) -> LAR | AS23: - | AT23: =IF(AR22="","",VLOOKUP(AR22,'[1]All Player'!$A$2:$D$517,4,FALSE)) -> RB | AU23: =AP23+0.01 -> 7.09 | AW23: =IF(AW22="","",VLOOKUP(AW22,'[1]All Player'!$A$2:$D$517,2,FALSE)) -> PIT | AX23: - | AY23: =IF(AW22="","",VLOOKUP(AW22,'[1]All Player'!$A$2:$D$517,4,FALSE)) -> QB | AZ23: =AU23+0.01 -> 7.1 | BB23: =IF(BB22="","",VLOOKUP(BB22,'[1]All Player'!$A$2:$D$517,2,FALSE)) -> SEA | BC23: - | BD23: =IF(BB22="","",VLOOKUP(BB22,'[1]All Player'!$A$2:$D$517,4,FALSE)) -> WR | BE23: =AZ23+0.01 -> 7.11 | BG23: =IF(BG22="","",VLOOKUP(BG22,'[1]All Player'!$A$2:$D$517,2,FALSE)) -> JAC | BH23: - | BI23: =IF(BG22="","",VLOOKUP(BG22,'[1]All Player'!$A$2:$D$517,4,FALSE)) -> QB | BJ23: =BE23+0.01 -> 7.12 | BL23: =IF(BL22="","",VLOOKUP(BL22,'[1]All Player'!$A$2:$D$517,2,FALSE)) -> LAC | BM23: - | BN23: =IF(BL22="","",VLOOKUP(BL22,'[1]All Player'!$A$2:$D$517,4,FALSE)) -> RB | BO23: =BJ23+0.01 -> 7.13 | BQ23: =IF(BQ22="","",VLOOKUP(BQ22,'[1]All Player'!$A$2:$D$517,2,FALSE)) -> ARI | BR23: - | BS23: =IF(BQ22="","",VLOOKUP(BQ22,'[1]All Player'!$A$2:$D$517,4,FALSE)) -> RB | BT23: =BO23+0.01 -> 7.14 | BV23: =IF(BV22="","",VLOOKUP(BV22,'[1]All Player'!$A$2:$D$517,2,FALSE)) -> BUF | BW23: - | BX23: =IF(BV22="","",VLOOKUP(BV22,'[1]All Player'!$A$2:$D$517,4,FALSE)) -> WR | BY23: =BT23+0.01 -> 7.15 | CA23: =IF(CA22="","",VLOOKUP(CA22,'[1]All Player'!$A$2:$D$517,2,FALSE)) -> TEN | CB23: - | CC23: =IF(CA22="","",VLOOKUP(CA22,'[1]All Player'!$A$2:$D$517,4,FALSE)) -> WR | CD23: =BY23+0.01 -> 7.16 | CF23: =IF(CF22="","",VLOOKUP(CF22,'[1]All Player'!$A$2:$D$517,2,FALSE)) -> DEN | CG23: - | CH23: =IF(CF22="","",VLOOKUP(CF22,'[1]All Player'!$A$2:$D$517,4,FALSE)) -> WR | CI23: =CD23+0.01 -> 7.17 | CK23: =IF(CK22="","",VLOOKUP(CK22,'[1]All Player'!$A$2:$D$517,2,FALSE)) -> SF | CL23: - | CM23: =IF(CK22="","",VLOOKUP(CK22,'[1]All Player'!$A$2:$D$517,4,FALSE)) -> DEF | CN23: =CI23+0.01 -> 7.18 | CP23: =IF(CP22="","",VLOOKUP(CP22,'[1]All Player'!$A$2:$D$517,2,FALSE)) -> MIN | CQ23: - | CR23: =IF(CP22="","",VLOOKUP(CP22,'[1]All Player'!$A$2:$D$517,4,FALSE)) -> WR | CS23: =CN23+0.01 -> 7.19 | CU23: =IF(CU22="","",VLOOKUP(CU22,'[1]All Player'!$A$2:$D$517,2,FALSE)) -> MIN | CV23: - | CW23: =IF(CU22="","",VLOOKUP(CU22,'[1]All Player'!$A$2:$D$517,4,FALSE)) -> RB | CX23: =CS23+0.01 -> 7.2
B25: 8. Runde | D25: Elijah Mitchell | I25: Alexander Mattison | N25: Josh Downs | S25: MarShawn Lloyd | X25: Derek Carr | AC25: Joshua Palmer | AH25: Mike Williams | AM25: Ray Davis | AR25: Baker Mayfield | AW25: Jakobi Meyers | BB25: Jerry Jeudy | BG25: Taysom Hill | BL25: Justin Herbert | BQ25: Brian Thomas Jr. | BV25: Jameson Williams | CA25: Tyler Conklin | CF25: Cleveland Browns | CK25: Brandin Cooks | CP25: Khalil Herbert | CU25: Tyler Allgeier
D26: =IF(D25="","",VLOOKUP(D25,'[1]All Player'!$A$2:$D$517,2,FALSE)) -> SF | E26: - | F26: =IF(D25="","",VLOOKUP(D25,'[1]All Player'!$A$2:$D$517,4,FALSE)) -> RB | G26: =LEFT(B25,1)+0.2 -> 8.2 | I26: =IF(I25="","",VLOOKUP(I25,'[1]All Player'!$A$2:$D$517,2,FALSE)) -> LV | J26: - | K26: =IF(I25="","",VLOOKUP(I25,'[1]All Player'!$A$2:$D$517,4,FALSE)) -> RB | L26: =G26-0.01 -> 8.19 | N26: =IF(N25="","",VLOOKUP(N25,'[1]All Player'!$A$2:$D$517,2,FALSE)) -> IND | O26: - | P26: =IF(N25="","",VLOOKUP(N25,'[1]All Player'!$A$2:$D$517,4,FALSE)) -> WR | Q26: =L26-0.01 -> 8.18 | S26: =IF(S25="","",VLOOKUP(S25,'[1]All Player'!$A$2:$D$517,2,FALSE)) -> GB | T26: - | U26: =IF(S25="","",VLOOKUP(S25,'[1]All Player'!$A$2:$D$517,4,FALSE)) -> RB | V26: =Q26-0.01 -> 8.17 | X26: =IF(X25="","",VLOOKUP(X25,'[1]All Player'!$A$2:$D$517,2,FALSE)) -> NO | Y26: - | Z26: =IF(X25="","",VLOOKUP(X25,'[1]All Player'!$A$2:$D$517,4,FALSE)) -> QB | AA26: =V26-0.01 -> 8.16 | AC26: =IF(AC25="","",VLOOKUP(AC25,'[1]All Player'!$A$2:$D$517,2,FALSE)) -> LAC | AD26: - | AE26: =IF(AC25="","",VLOOKUP(AC25,'[1]All Player'!$A$2:$D$517,4,FALSE)) -> WR | AF26: =AA26-0.01 -> 8.15 | AH26: =IF(AH25="","",VLOOKUP(AH25,'[1]All Player'!$A$2:$D$517,2,FALSE)) -> NYJ | AI26: - | AJ26: =IF(AH25="","",VLOOKUP(AH25,'[1]All Player'!$A$2:$D$517,4,FALSE)) -> WR | AK26: =AF26-0.01 -> 8.14 | AM26: =IF(AM25="","",VLOOKUP(AM25,'[1]All Player'!$A$2:$D$517,2,FALSE)) -> BUF | AN26: - | AO26: =IF(AM25="","",VLOOKUP(AM25,'[1]All Player'!$A$2:$D$517,4,FALSE)) -> RB | AP26: =AK26-0.01 -> 8.13 | AR26: =IF(AR25="","",VLOOKUP(AR25,'[1]All Player'!$A$2:$D$517,2,FALSE)) -> TB | AS26: - | AT26: =IF(AR25="","",VLOOKUP(AR25,'[1]All Player'!$A$2:$D$517,4,FALSE)) -> QB | AU26: =AP26-0.01 -> 8.12 | AW26: =IF(AW25="","",VLOOKUP(AW25,'[1]All Player'!$A$2:$D$517,2,FALSE)) -> LV | AX26: - | AY26: =IF(AW25="","",VLOOKUP(AW25,'[1]All Player'!$A$2:$D$517,4,FALSE)) -> WR | AZ26: =AU26-0.01 -> 8.11 | BB26: =IF(BB25="","",VLOOKUP(BB25,'[1]All Player'!$A$2:$D$517,2,FALSE)) -> CLE | BC26: - | BD26: =IF(BB25="","",VLOOKUP(BB25,'[1]All Player'!$A$2:$D$517,4,FALSE)) -> WR | BE26: =AZ26-0.01 -> 8.1 | BG26: =IF(BG25="","",VLOOKUP(BG25,'[1]All Player'!$A$2:$D$517,2,FALSE)) -> NO | BH26: - | BI26: =IF(BG25="","",VLOOKUP(BG25,'[1]All Player'!$A$2:$D$517,4,FALSE)) -> TE | BJ26: =BE26-0.01 -> 8.09 | BL26: =IF(BL25="","",VLOOKUP(BL25,'[1]All Player'!$A$2:$D$517,2,FALSE)) -> LAC | BM26: - | BN26: =IF(BL25="","",VLOOKUP(BL25,'[1]All Player'!$A$2:$D$517,4,FALSE)) -> QB | BO26: =BJ26-0.01 -> 8.08 | BQ26: =IF(BQ25="","",VLOOKUP(BQ25,'[1]All Player'!$A$2:$D$517,2,FALSE)) -> JAC | BR26: - | BS26: =IF(BQ25="","",VLOOKUP(BQ25,'[1]All Player'!$A$2:$D$517,4,FALSE)) -> WR | BT26: =BO26-0.01 -> 8.07 | BV26: =IF(BV25="","",VLOOKUP(BV25,'[1]All Player'!$A$2:$D$517,2,FALSE)) -> DET | BW26: - | BX26: =IF(BV25="","",VLOOKUP(BV25,'[1]All Player'!$A$2:$D$517,4,FALSE)) -> WR | BY26: =BT26-0.01 -> 8.06 | CA26: =IF(CA25="","",VLOOKUP(CA25,'[1]All Player'!$A$2:$D$517,2,FALSE)) -> NYJ | CB26: - | CC26: =IF(CA25="","",VLOOKUP(CA25,'[1]All Player'!$A$2:$D$517,4,FALSE)) -> TE | CD26: =BY26-0.01 -> 8.05 | CF26: =IF(CF25="","",VLOOKUP(CF25,'[1]All Player'!$A$2:$D$517,2,FALSE)) -> CLE | CG26: - | CH26: =IF(CF25="","",VLOOKUP(CF25,'[1]All Player'!$A$2:$D$517,4,FALSE)) -> DEF | CI26: =CD26-0.01 -> 8.04 | CK26: =IF(CK25="","",VLOOKUP(CK25,'[1]All Player'!$A$2:$D$517,2,FALSE)) -> DAL | CL26: - | CM26: =IF(CK25="","",VLOOKUP(CK25,'[1]All Player'!$A$2:$D$517,4,FALSE)) -> WR | CN26: =CI26-0.01 -> 8.03 | CP26: =IF(CP25="","",VLOOKUP(CP25,'[1]All Player'!$A$2:$D$517,2,FALSE)) -> CHI | CQ26: - | CR26: =IF(CP25="","",VLOOKUP(CP25,'[1]All Player'!$A$2:$D$517,4,FALSE)) -> RB | CS26: =CN26-0.01 -> 8.02 | CU26: =IF(CU25="","",VLOOKUP(CU25,'[1]All Player'!$A$2:$D$517,2,FALSE)) -> ATL | CV26: - | CW26: =IF(CU25="","",VLOOKUP(CU25,'[1]All Player'!$A$2:$D$517,4,FALSE)) -> RB | CX26: =CS26-0.01 -> 8.01
B28: 9. Runde | D28: Braelon Allen | I28: Ja'Lynn Polk | N28: Chigoziem Okonkwo | S28: KImani VIdal | X28: Curtis Samuel | AC28: Roschon Johnson | AH28: Bucky Irving | AM28: Rashid Shaheed | AR28: Adonai Mitchell | AW28: Kendre Miller | BB28: Kendrick Bourne | BG28: Jaylen Wright | BL28: Khalil Shakir | BQ28: Adam Thielen | BV28: Tyrone Tracy Jr. | CA28: Audric Estime | CF28: Dameon Pierce | CK28: Geno Smith | CP28: Dallas Cowboys | CU28: Ben Sinnott
D29: =IF(D28="","",VLOOKUP(D28,'[1]All Player'!$A$2:$D$517,2,FALSE)) -> NYJ | E29: - | F29: =IF(D28="","",VLOOKUP(D28,'[1]All Player'!$A$2:$D$517,4,FALSE)) -> RB | G29: =LEFT(B28,1)+0.01 -> 9.01 | I29: =IF(I28="","",VLOOKUP(I28,'[1]All Player'!$A$2:$D$517,2,FALSE)) -> NE | J29: - | K29: =IF(I28="","",VLOOKUP(I28,'[1]All Player'!$A$2:$D$517,4,FALSE)) -> WR | L29: =G29+0.01 -> 9.02 | N29: =IF(N28="","",VLOOKUP(N28,'[1]All Player'!$A$2:$D$517,2,FALSE)) -> TEN | O29: - | P29: =IF(N28="","",VLOOKUP(N28,'[1]All Player'!$A$2:$D$517,4,FALSE)) -> TE | Q29: =L29+0.01 -> 9.03 | S29: =IF(S28="","",VLOOKUP(S28,'[1]All Player'!$A$2:$D$517,2,FALSE)) -> LAC | T29: - | U29: =IF(S28="","",VLOOKUP(S28,'[1]All Player'!$A$2:$D$517,4,FALSE)) -> RB | V29: =Q29+0.01 -> 9.04 | X29: =IF(X28="","",VLOOKUP(X28,'[1]All Player'!$A$2:$D$517,2,FALSE)) -> BUF | Y29: - | Z29: =IF(X28="","",VLOOKUP(X28,'[1]All Player'!$A$2:$D$517,4,FALSE)) -> WR | AA29: =V29+0.01 -> 9.05 | AC29: =IF(AC28="","",VLOOKUP(AC28,'[1]All Player'!$A$2:$D$517,2,FALSE)) -> CHI | AD29: - | AE29: =IF(AC28="","",VLOOKUP(AC28,'[1]All Player'!$A$2:$D$517,4,FALSE)) -> RB | AF29: =AA29+0.01 -> 9.06 | AH29: =IF(AH28="","",VLOOKUP(AH28,'[1]All Player'!$A$2:$D$517,2,FALSE)) -> TB | AI29: - | AJ29: =IF(AH28="","",VLOOKUP(AH28,'[1]All Player'!$A$2:$D$517,4,FALSE)) -> RB | AK29: =AF29+0.01 -> 9.07 | AM29: =IF(AM28="","",VLOOKUP(AM28,'[1]All Player'!$A$2:$D$517,2,FALSE)) -> NO | AN29: - | AO29: =IF(AM28="","",VLOOKUP(AM28,'[1]All Player'!$A$2:$D$517,4,FALSE)) -> WR | AP29: =AK29+0.01 -> 9.08 | AR29: =IF(AR28="","",VLOOKUP(AR28,'[1]All Player'!$A$2:$D$517,2,FALSE)) -> IND | AS29: - | AT29: =IF(AR28="","",VLOOKUP(AR28,'[1]All Player'!$A$2:$D$517,4,FALSE)) -> WR | AU29: =AP29+0.01 -> 9.09 | AW29: =IF(AW28="","",VLOOKUP(AW28,'[1]All Player'!$A$2:$D$517,2,FALSE)) -> NO | AX29: - | AY29: =IF(AW28="","",VLOOKUP(AW28,'[1]All Player'!$A$2:$D$517,4,FALSE)) -> RB | AZ29: =AU29+0.01 -> 9.1 | BB29: =IF(BB28="","",VLOOKUP(BB28,'[1]All Player'!$A$2:$D$517,2,FALSE)) -> NE | BC29: - | BD29: =IF(BB28="","",VLOOKUP(BB28,'[1]All Player'!$A$2:$D$517,4,FALSE)) -> WR | BE29: =AZ29+0.01 -> 9.11 | BG29: =IF(BG28="","",VLOOKUP(BG28,'[1]All Player'!$A$2:$D$517,2,FALSE)) -> MIA | BH29: - | BI29: =IF(BG28="","",VLOOKUP(BG28,'[1]All Player'!$A$2:$D$517,4,FALSE)) -> RB | BJ29: =BE29+0.01 -> 9.12 | BL29: =IF(BL28="","",VLOOKUP(BL28,'[1]All Player'!$A$2:$D$517,2,FALSE)) -> BUF | BM29: - | BN29: =IF(BL28="","",VLOOKUP(BL28,'[1]All Player'!$A$2:$D$517,4,FALSE)) -> WR | BO29: =BJ29+0.01 -> 9.13 | BQ29: =IF(BQ28="","",VLOOKUP(BQ28,'[1]All Player'!$A$2:$D$517,2,FALSE)) -> CAR | BR29: - | BS29: =IF(BQ28="","",VLOOKUP(BQ28,'[1]All Player'!$A$2:$D$517,4,FALSE)) -> WR | BT29: =BO29+0.01 -> 9.14 | BV29: =IF(BV28="","",VLOOKUP(BV28,'[1]All Player'!$A$2:$D$517,2,FALSE)) -> NYG | BW29: - | BX29: =IF(BV28="","",VLOOKUP(BV28,'[1]All Player'!$A$2:$D$517,4,FALSE)) -> RB | BY29: =BT29+0.01 -> 9.15 | CA29: =IF(CA28="","",VLOOKUP(CA28,'[1]All Player'!$A$2:$D$517,2,FALSE)) -> DEN | CB29: - | CC29: =IF(CA28="","",VLOOKUP(CA28,'[1]All Player'!$A$2:$D$517,4,FALSE)) -> RB | CD29: =BY29+0.01 -> 9.16 | CF29: =IF(CF28="","",VLOOKUP(CF28,'[1]All Player'!$A$2:$D$517,2,FALSE)) -> HOU | CG29: - | CH29: =IF(CF28="","",VLOOKUP(CF28,'[1]All Player'!$A$2:$D$517,4,FALSE)) -> RB | CI29: =CD29+0.01 -> 9.17 | CK29: =IF(CK28="","",VLOOKUP(CK28,'[1]All Player'!$A$2:$D$517,2,FALSE)) -> SEA | CL29: - | CM29: =IF(CK28="","",VLOOKUP(CK28,'[1]All Player'!$A$2:$D$517,4,FALSE)) -> QB | CN29: =CI29+0.01 -> 9.18 | CP29: =IF(CP28="","",VLOOKUP(CP28,'[1]All Player'!$A$2:$D$517,2,FALSE)) -> DAL | CQ29: - | CR29: =IF(CP28="","",VLOOKUP(CP28,'[1]All Player'!$A$2:$D$517,4,FALSE)) -> DEF | CS29: =CN29+0.01 -> 9.19 | CU29: =IF(CU28="","",VLOOKUP(CU28,'[1]All Player'!$A$2:$D$517,2,FALSE)) -> WAS | CV29: - | CW29: =IF(CU28="","",VLOOKUP(CU28,'[1]All Player'!$A$2:$D$517,4,FALSE)) -> TE | CX29: =CS29+0.01 -> 9.2
B31: 10. Runde | D31: Rashod Bateman | I31: Drake Maye | N31: Sam Darnold | S31: DeMario Douglas | X31: Justice Hill | AC31: Jason Sanders | AH31: Jonnu Smith | AM31: MIke Gesicki | AR31: Isaiah Likely | AW31: Juwan Johnson | BB31: Bryce Young | BG31: Clyde Edwards-Helaire | BL31: Noah Fant | BQ31: Daniel Jones | BV31: Will Levis | CA31: Dylan Laube | CF31: Brandon Aubrey | CK31: Cade Otton | CP31: Evan McPherson | CU31: Harrison Butker
D32: =IF(D31="","",VLOOKUP(D31,'[1]All Player'!$A$2:$D$517,2,FALSE)) -> BAL | E32: - | F32: =IF(D31="","",VLOOKUP(D31,'[1]All Player'!$A$2:$D$517,4,FALSE)) -> WR | G32: =LEFT(B31,2)+0.2 -> 10.2 | I32: =IF(I31="","",VLOOKUP(I31,'[1]All Player'!$A$2:$D$517,2,FALSE)) -> NE | J32: - | K32: =IF(I31="","",VLOOKUP(I31,'[1]All Player'!$A$2:$D$517,4,FALSE)) -> QB | L32: =G32-0.01 -> 10.19 | N32: =IF(N31="","",VLOOKUP(N31,'[1]All Player'!$A$2:$D$517,2,FALSE)) -> MIN | O32: - | P32: =IF(N31="","",VLOOKUP(N31,'[1]All Player'!$A$2:$D$517,4,FALSE)) -> QB | Q32: =L32-0.01 -> 10.18 | S32: =IF(S31="","",VLOOKUP(S31,'[1]All Player'!$A$2:$D$517,2,FALSE)) -> NE | T32: - | U32: =IF(S31="","",VLOOKUP(S31,'[1]All Player'!$A$2:$D$517,4,FALSE)) -> WR | V32: =Q32-0.01 -> 10.17 | X32: =IF(X31="","",VLOOKUP(X31,'[1]All Player'!$A$2:$D$517,2,FALSE)) -> BAL | Y32: - | Z32: =IF(X31="","",VLOOKUP(X31,'[1]All Player'!$A$2:$D$517,4,FALSE)) -> RB | AA32: =V32-0.01 -> 10.16 | AC32: =IF(AC31="","",VLOOKUP(AC31,'[1]All Player'!$A$2:$D$517,2,FALSE)) -> MIA | AD32: - | AE32: =IF(AC31="","",VLOOKUP(AC31,'[1]All Player'!$A$2:$D$517,4,FALSE)) -> K | AF32: =AA32-0.01 -> 10.15 | AH32: =IF(AH31="","",VLOOKUP(AH31,'[1]All Player'!$A$2:$D$517,2,FALSE)) -> MIA | AI32: - | AJ32: =IF(AH31="","",VLOOKUP(AH31,'[1]All Player'!$A$2:$D$517,4,FALSE)) -> TE | AK32: =AF32-0.01 -> 10.14 | AM32: =IF(AM31="","",VLOOKUP(AM31,'[1]All Player'!$A$2:$D$517,2,FALSE)) -> CIN | AN32: - | AO32: =IF(AM31="","",VLOOKUP(AM31,'[1]All Player'!$A$2:$D$517,4,FALSE)) -> TE | AP32: =AK32-0.01 -> 10.13 | AR32: =IF(AR31="","",VLOOKUP(AR31,'[1]All Player'!$A$2:$D$517,2,FALSE)) -> BAL | AS32: - | AT32: =IF(AR31="","",VLOOKUP(AR31,'[1]All Player'!$A$2:$D$517,4,FALSE)) -> TE | AU32: =AP32-0.01 -> 10.12 | AW32: =IF(AW31="","",VLOOKUP(AW31,'[1]All Player'!$A$2:$D$517,2,FALSE)) -> NO | AX32: - | AY32: =IF(AW31="","",VLOOKUP(AW31,'[1]All Player'!$A$2:$D$517,4,FALSE)) -> TE | AZ32: =AU32-0.01 -> 10.11 | BB32: =IF(BB31="","",VLOOKUP(BB31,'[1]All Player'!$A$2:$D$517,2,FALSE)) -> CAR | BC32: - | BD32: =IF(BB31="","",VLOOKUP(BB31,'[1]All Player'!$A$2:$D$517,4,FALSE)) -> QB | BE32: =AZ32-0.01 -> 10.1 | BG32: =IF(BG31="","",VLOOKUP(BG31,'[1]All Player'!$A$2:$D$517,2,FALSE)) -> KC | BH32: - | BI32: =IF(BG31="","",VLOOKUP(BG31,'[1]All Player'!$A$2:$D$517,4,FALSE)) -> RB | BJ32: =BE32-0.01 -> 10.09 | BL32: =IF(BL31="","",VLOOKUP(BL31,'[1]All Player'!$A$2:$D$517,2,FALSE)) -> SEA | BM32: - | BN32: =IF(BL31="","",VLOOKUP(BL31,'[1]All Player'!$A$2:$D$517,4,FALSE)) -> TE | BO32: =BJ32-0.01 -> 10.08 | BQ32: =IF(BQ31="","",VLOOKUP(BQ31,'[1]All Player'!$A$2:$D$517,2,FALSE)) -> NYG | BR32: - | BS32: =IF(BQ31="","",VLOOKUP(BQ31,'[1]All Player'!$A$2:$D$517,4,FALSE)) -> QB | BT32: =BO32-0.01 -> 10.07 | BV32: =IF(BV31="","",VLOOKUP(BV31,'[1]All Player'!$A$2:$D$517,2,FALSE)) -> TEN | BW32: - | BX32: =IF(BV31="","",VLOOKUP(BV31,'[1]All Player'!$A$2:$D$517,4,FALSE)) -> QB | BY32: =BT32-0.01 -> 10.06 | CA32: =IF(CA31="","",VLOOKUP(CA31,'[1]All Player'!$A$2:$D$517,2,FALSE)) -> LV | CB32: - | CC32: =IF(CA31="","",VLOOKUP(CA31,'[1]All Player'!$A$2:$D$517,4,FALSE)) -> RB | CD32: =BY32-0.01 -> 10.05 | CF32: =IF(CF31="","",VLOOKUP(CF31,'[1]All Player'!$A$2:$D$517,2,FALSE)) -> DAL | CG32: - | CH32: =IF(CF31="","",VLOOKUP(CF31,'[1]All Player'!$A$2:$D$517,4,FALSE)) -> K | CI32: =CD32-0.01 -> 10.04 | CK32: =IF(CK31="","",VLOOKUP(CK31,'[1]All Player'!$A$2:$D$517,2,FALSE)) -> TB | CL32: - | CM32: =IF(CK31="","",VLOOKUP(CK31,'[1]All Player'!$A$2:$D$517,4,FALSE)) -> TE | CN32: =CI32-0.01 -> 10.03 | CP32: =IF(CP31="","",VLOOKUP(CP31,'[1]All Player'!$A$2:$D$517,2,FALSE)) -> CIN | CQ32: - | CR32: =IF(CP31="","",VLOOKUP(CP31,'[1]All Player'!$A$2:$D$517,4,FALSE)) -> K | CS32: =CN32-0.01 -> 10.02 | CU32: =IF(CU31="","",VLOOKUP(CU31,'[1]All Player'!$A$2:$D$517,2,FALSE)) -> KC | CV32: - | CW32: =IF(CU31="","",VLOOKUP(CU31,'[1]All Player'!$A$2:$D$517,4,FALSE)) -> K | CX32: =CS32-0.01 -> 10.01
B34: 11. Runde | D34: New York Jets | I34: Kenneth Gainwell | N34: D'Onta Foreman | S34: Luke McCaffrey | X34: Pittsburgh Steelers | AC34: Kansas City Chiefs | AH34: Buffalo Bills | AM34: Ka'imi Fairbairn | AR34: Houston Texans | AW34: AJ Dillon | BB34: Jake Moody | BG34: Philadelphia Eagles | BL34: Tank Bigsby | BQ34: Miles Sanders | BV34: Keaton Mitchell | CA34: Tucker Kraft | CF34: Jamaal Williams | CK34: Dalvin Cook | CP34: Justin Fields | CU34: Tampa Bay Buccaneers
D35: =IF(D34="","",VLOOKUP(D34,'[1]All Player'!$A$2:$D$517,2,FALSE)) -> NYJ | E35: - | F35: =IF(D34="","",VLOOKUP(D34,'[1]All Player'!$A$2:$D$517,4,FALSE)) -> DEF | G35: =LEFT(B34,2)+0.01 -> 11.01 | I35: =IF(I34="","",VLOOKUP(I34,'[1]All Player'!$A$2:$D$517,2,FALSE)) -> PHI | J35: - | K35: =IF(I34="","",VLOOKUP(I34,'[1]All Player'!$A$2:$D$517,4,FALSE)) -> RB | L35: =G35+0.01 -> 11.02 | N35: =IF(N34="","",VLOOKUP(N34,'[1]All Player'!$A$2:$D$517,2,FALSE)) -> CLE | O35: - | P35: =IF(N34="","",VLOOKUP(N34,'[1]All Player'!$A$2:$D$517,4,FALSE)) -> RB | Q35: =L35+0.01 -> 11.03 | S35: =IF(S34="","",VLOOKUP(S34,'[1]All Player'!$A$2:$D$517,2,FALSE)) -> WAS | T35: - | U35: =IF(S34="","",VLOOKUP(S34,'[1]All Player'!$A$2:$D$517,4,FALSE)) -> WR | V35: =Q35+0.01 -> 11.04 | X35: =IF(X34="","",VLOOKUP(X34,'[1]All Player'!$A$2:$D$517,2,FALSE)) -> PIT | Y35: - | Z35: =IF(X34="","",VLOOKUP(X34,'[1]All Player'!$A$2:$D$517,4,FALSE)) -> DEF | AA35: =V35+0.01 -> 11.05 | AC35: =IF(AC34="","",VLOOKUP(AC34,'[1]All Player'!$A$2:$D$517,2,FALSE)) -> KC | AD35: - | AE35: =IF(AC34="","",VLOOKUP(AC34,'[1]All Player'!$A$2:$D$517,4,FALSE)) -> DEF | AF35: =AA35+0.01 -> 11.06 | AH35: =IF(AH34="","",VLOOKUP(AH34,'[1]All Player'!$A$2:$D$517,2,FALSE)) -> BUF | AI35: - | AJ35: =IF(AH34="","",VLOOKUP(AH34,'[1]All Player'!$A$2:$D$517,4,FALSE)) -> DEF | AK35: =AF35+0.01 -> 11.07 | AM35: =IF(AM34="","",VLOOKUP(AM34,'[1]All Player'!$A$2:$D$517,2,FALSE)) -> HOU | AN35: - | AO35: =IF(AM34="","",VLOOKUP(AM34,'[1]All Player'!$A$2:$D$517,4,FALSE)) -> K | AP35: =AK35+0.01 -> 11.08 | AR35: =IF(AR34="","",VLOOKUP(AR34,'[1]All Player'!$A$2:$D$517,2,FALSE)) -> HOU | AS35: - | AT35: =IF(AR34="","",VLOOKUP(AR34,'[1]All Player'!$A$2:$D$517,4,FALSE)) -> DEF | AU35: =AP35+0.01 -> 11.09 | AW35: =IF(AW34="","",VLOOKUP(AW34,'[1]All Player'!$A$2:$D$517,2,FALSE)) -> GB | AX35: - | AY35: =IF(AW34="","",VLOOKUP(AW34,'[1]All Player'!$A$2:$D$517,4,FALSE)) -> RB | AZ35: =AU35+0.01 -> 11.1 | BB35: =IF(BB34="","",VLOOKUP(BB34,'[1]All Player'!$A$2:$D$517,2,FALSE)) -> SF | BC35: - | BD35: =IF(BB34="","",VLOOKUP(BB34,'[1]All Player'!$A$2:$D$517,4,FALSE)) -> K | BE35: =AZ35+0.01 -> 11.11 | BG35: =IF(BG34="","",VLOOKUP(BG34,'[1]All Player'!$A$2:$D$517,2,FALSE)) -> PHI | BH35: - | BI35: =IF(BG34="","",VLOOKUP(BG34,'[1]All Player'!$A$2:$D$517,4,FALSE)) -> DEF | BJ35: =BE35+0.01 -> 11.12 | BL35: =IF(BL34="","",VLOOKUP(BL34,'[1]All Player'!$A$2:$D$517,2,FALSE)) -> JAC | BM35: - | BN35: =IF(BL34="","",VLOOKUP(BL34,'[1]All Player'!$A$2:$D$517,4,FALSE)) -> RB | BO35: =BJ35+0.01 -> 11.13 | BQ35: =IF(BQ34="","",VLOOKUP(BQ34,'[1]All Player'!$A$2:$D$517,2,FALSE)) -> CAR | BR35: - | BS35: =IF(BQ34="","",VLOOKUP(BQ34,'[1]All Player'!$A$2:$D$517,4,FALSE)) -> RB | BT35: =BO35+0.01 -> 11.14 | BV35: =IF(BV34="","",VLOOKUP(BV34,'[1]All Player'!$A$2:$D$517,2,FALSE)) -> BAL | BW35: - | BX35: =IF(BV34="","",VLOOKUP(BV34,'[1]All Player'!$A$2:$D$517,4,FALSE)) -> RB | BY35: =BT35+0.01 -> 11.15 | CA35: =IF(CA34="","",VLOOKUP(CA34,'[1]All Player'!$A$2:$D$517,2,FALSE)) -> GB | CB35: - | CC35: =IF(CA34="","",VLOOKUP(CA34,'[1]All Player'!$A$2:$D$517,4,FALSE)) -> TE | CD35: =BY35+0.01 -> 11.16 | CF35: =IF(CF34="","",VLOOKUP(CF34,'[1]All Player'!$A$2:$D$517,2,FALSE)) -> NO | CG35: - | CH35: =IF(CF34="","",VLOOKUP(CF34,'[1]All Player'!$A$2:$D$517,4,FALSE)) -> RB | CI35: =CD35+0.01 -> 11.17 | CK35: =IF(CK34="","",VLOOKUP(CK34,'[1]All Player'!$A$2:$D$517,2,FALSE)) -> FA | CL35: - | CM35: =IF(CK34="","",VLOOKUP(CK34,'[1]All Player'!$A$2:$D$517,4,FALSE)) -> RB | CN35: =CI35+0.01 -> 11.18 | CP35: =IF(CP34="","",VLOOKUP(CP34,'[1]All Player'!$A$2:$D$517,2,FALSE)) -> PIT | CQ35: - | CR35: =IF(CP34="","",VLOOKUP(CP34,'[1]All Player'!$A$2:$D$517,4,FALSE)) -> QB | CS35: =CN35+0.01 -> 11.19 | CU35: =IF(CU34="","",VLOOKUP(CU34,'[1]All Player'!$A$2:$D$517,2,FALSE)) -> TB | CV35: - | CW35: =IF(CU34="","",VLOOKUP(CU34,'[1]All Player'!$A$2:$D$517,4,FALSE)) -> DEF | CX35: =CS35+0.01 -> 11.2
B37: 12. Runde | D37: Dawson Knox | I37: Tyler Higbee | N37: Jalen McMIllan | S37: Hayden Hurst | X37: Tyler Boyd | AC37: Michael Mayer | AH37: Trey Sermon | AM37: Gardner Minshew II | AR37: WIll Shipley | AW37: Wan'Dale Robinson | BB37: Miami Dolphins | BG37: Michael Wilson | BL37: Darnell Mooney | BQ37: Jahan Dotson | BV37: Chicago Bears | CA37: Dontayvion Wicks | CF37: Gabe Davis | CK37: Tyler Bass | CP37: Darren Waller | CU37: Xavier Legette
D38: =IF(D37="","",VLOOKUP(D37,'[1]All Player'!$A$2:$D$517,2,FALSE)) -> BUF | E38: - | F38: =IF(D37="","",VLOOKUP(D37,'[1]All Player'!$A$2:$D$517,4,FALSE)) -> TE | G38: =LEFT(B37,2)+0.2 -> 12.2 | I38: =IF(I37="","",VLOOKUP(I37,'[1]All Player'!$A$2:$D$517,2,FALSE)) -> LAR | J38: - | K38: =IF(I37="","",VLOOKUP(I37,'[1]All Player'!$A$2:$D$517,4,FALSE)) -> TE | L38: =G38-0.01 -> 12.19 | N38: =IF(N37="","",VLOOKUP(N37,'[1]All Player'!$A$2:$D$517,2,FALSE)) -> TB | O38: - | P38: =IF(N37="","",VLOOKUP(N37,'[1]All Player'!$A$2:$D$517,4,FALSE)) -> WR | Q38: =L38-0.01 -> 12.18 | S38: =IF(S37="","",VLOOKUP(S37,'[1]All Player'!$A$2:$D$517,2,FALSE)) -> LAC | T38: - | U38: =IF(S37="","",VLOOKUP(S37,'[1]All Player'!$A$2:$D$517,4,FALSE)) -> TE | V38: =Q38-0.01 -> 12.17 | X38: =IF(X37="","",VLOOKUP(X37,'[1]All Player'!$A$2:$D$517,2,FALSE)) -> TEN | Y38: - | Z38: =IF(X37="","",VLOOKUP(X37,'[1]All Player'!$A$2:$D$517,4,FALSE)) -> WR | AA38: =V38-0.01 -> 12.16 | AC38: =IF(AC37="","",VLOOKUP(AC37,'[1]All Player'!$A$2:$D$517,2,FALSE)) -> LV | AD38: - | AE38: =IF(AC37="","",VLOOKUP(AC37,'[1]All Player'!$A$2:$D$517,4,FALSE)) -> TE | AF38: =AA38-0.01 -> 12.15 | AH38: =IF(AH37="","",VLOOKUP(AH37,'[1]All Player'!$A$2:$D$517,2,FALSE)) -> IND | AI38: - | AJ38: =IF(AH37="","",VLOOKUP(AH37,'[1]All Player'!$A$2:$D$517,4,FALSE)) -> RB | AK38: =AF38-0.01 -> 12.14 | AM38: =IF(AM37="","",VLOOKUP(AM37,'[1]All Player'!$A$2:$D$517,2,FALSE)) -> LV | AN38: - | AO38: =IF(AM37="","",VLOOKUP(AM37,'[1]All Player'!$A$2:$D$517,4,FALSE)) -> QB | AP38: =AK38-0.01 -> 12.13 | AR38: =IF(AR37="","",VLOOKUP(AR37,'[1]All Player'!$A$2:$D$517,2,FALSE)) -> PHI | AS38: - | AT38: =IF(AR37="","",VLOOKUP(AR37,'[1]All Player'!$A$2:$D$517,4,FALSE)) -> RB | AU38: =AP38-0.01 -> 12.12 | AW38: =IF(AW37="","",VLOOKUP(AW37,'[1]All Player'!$A$2:$D$517,2,FALSE)) -> NYG | AX38: - | AY38: =IF(AW37="","",VLOOKUP(AW37,'[1]All Player'!$A$2:$D$517,4,FALSE)) -> WR | AZ38: =AU38-0.01 -> 12.11 | BB38: =IF(BB37="","",VLOOKUP(BB37,'[1]All Player'!$A$2:$D$517,2,FALSE)) -> MIA | BC38: - | BD38: =IF(BB37="","",VLOOKUP(BB37,'[1]All Player'!$A$2:$D$517,4,FALSE)) -> DEF | BE38: =AZ38-0.01 -> 12.1 | BG38: =IF(BG37="","",VLOOKUP(BG37,'[1]All Player'!$A$2:$D$517,2,FALSE)) -> ARI | BH38: - | BI38: =IF(BG37="","",VLOOKUP(BG37,'[1]All Player'!$A$2:$D$517,4,FALSE)) -> WR | BJ38: =BE38-0.01 -> 12.09 | BL38: =IF(BL37="","",VLOOKUP(BL37,'[1]All Player'!$A$2:$D$517,2,FALSE)) -> ATL | BM38: - | BN38: =IF(BL37="","",VLOOKUP(BL37,'[1]All Player'!$A$2:$D$517,4,FALSE)) -> WR | BO38: =BJ38-0.01 -> 12.08 | BQ38: =IF(BQ37="","",VLOOKUP(BQ37,'[1]All Player'!$A$2:$D$517,2,FALSE)) -> WAS | BR38: - | BS38: =IF(BQ37="","",VLOOKUP(BQ37,'[1]All Player'!$A$2:$D$517,4,FALSE)) -> WR | BT38: =BO38-0.01 -> 12.07 | BV38: =IF(BV37="","",VLOOKUP(BV37,'[1]All Player'!$A$2:$D$517,2,FALSE)) -> CHI | BW38: - | BX38: =IF(BV37="","",VLOOKUP(BV37,'[1]All Player'!$A$2:$D$517,4,FALSE)) -> DEF | BY38: =BT38-0.01 -> 12.06 | CA38: =IF(CA37="","",VLOOKUP(CA37,'[1]All Player'!$A$2:$D$517,2,FALSE)) -> GB | CB38: - | CC38: =IF(CA37="","",VLOOKUP(CA37,'[1]All Player'!$A$2:$D$517,4,FALSE)) -> WR | CD38: =BY38-0.01 -> 12.05 | CF38: =IF(CF37="","",VLOOKUP(CF37,'[1]All Player'!$A$2:$D$517,2,FALSE)) -> JAC | CG38: - | CH38: =IF(CF37="","",VLOOKUP(CF37,'[1]All Player'!$A$2:$D$517,4,FALSE)) -> WR | CI38: =CD38-0.01 -> 12.04 | CK38: =IF(CK37="","",VLOOKUP(CK37,'[1]All Player'!$A$2:$D$517,2,FALSE)) -> BUF | CL38: - | CM38: =IF(CK37="","",VLOOKUP(CK37,'[1]All Player'!$A$2:$D$517,4,FALSE)) -> K | CN38: =CI38-0.01 -> 12.03 | CP38: FA | CQ38: - | CR38: TE | CS38: =CN38-0.01 -> 12.02 | CU38: =IF(CU37="","",VLOOKUP(CU37,'[1]All Player'!$A$2:$D$517,2,FALSE)) -> CAR | CV38: - | CW38: =IF(CU37="","",VLOOKUP(CU37,'[1]All Player'!$A$2:$D$517,4,FALSE)) -> WR | CX38: =CS38-0.01 -> 12.01
B40: 13. Runde | D40: Younghoe Koo | I40: Detroit Lions | N40: Indianapolis Colts | S40: Roman Wilson | X40: Jacoby Brissett | AC40: Aidan O'Connell | AH40: Ja'Tavion Sanders | AM40: New Orleans Saints | AR40: Ricky Pearsall | AW40: Michael Penix Jr. | BB40: Daniel Bellinger | BG40: Samaje Perine | BL40: Marvin Mims Jr. | BQ40: Zach Ertz | BV40: Greg Dulcich | CA40: Green Bay Packers | CF40: Sam Howell | CK40: Jordan Mason | CP40: Demarcus Robinson | CU40: Darius Slayton
D41: =IF(D40="","",VLOOKUP(D40,'[1]All Player'!$A$2:$D$517,2,FALSE)) -> ATL | E41: - | F41: =IF(D40="","",VLOOKUP(D40,'[1]All Player'!$A$2:$D$517,4,FALSE)) -> K | G41: =LEFT(B40,2)+0.01 -> 13.01 | I41: =IF(I40="","",VLOOKUP(I40,'[1]All Player'!$A$2:$D$517,2,FALSE)) -> DET | J41: - | K41: =IF(I40="","",VLOOKUP(I40,'[1]All Player'!$A$2:$D$517,4,FALSE)) -> DEF | L41: =G41+0.01 -> 13.02 | N41: =IF(N40="","",VLOOKUP(N40,'[1]All Player'!$A$2:$D$517,2,FALSE)) -> IND | O41: - | P41: =IF(N40="","",VLOOKUP(N40,'[1]All Player'!$A$2:$D$517,4,FALSE)) -> DEF | Q41: =L41+0.01 -> 13.03 | S41: =IF(S40="","",VLOOKUP(S40,'[1]All Player'!$A$2:$D$517,2,FALSE)) -> PIT | T41: - | U41: =IF(S40="","",VLOOKUP(S40,'[1]All Player'!$A$2:$D$517,4,FALSE)) -> WR | V41: =Q41+0.01 -> 13.04 | X41: =IF(X40="","",VLOOKUP(X40,'[1]All Player'!$A$2:$D$517,2,FALSE)) -> NE | Y41: - | Z41: =IF(X40="","",VLOOKUP(X40,'[1]All Player'!$A$2:$D$517,4,FALSE)) -> QB | AA41: =V41+0.01 -> 13.05 | AC41: =IF(AC40="","",VLOOKUP(AC40,'[1]All Player'!$A$2:$D$517,2,FALSE)) -> LV | AD41: - | AE41: =IF(AC40="","",VLOOKUP(AC40,'[1]All Player'!$A$2:$D$517,4,FALSE)) -> QB | AF41: =AA41+0.01 -> 13.06 | AH41: =IF(AH40="","",VLOOKUP(AH40,'[1]All Player'!$A$2:$D$517,2,FALSE)) -> CAR | AI41: - | AJ41: =IF(AH40="","",VLOOKUP(AH40,'[1]All Player'!$A$2:$D$517,4,FALSE)) -> TE | AK41: =AF41+0.01 -> 13.07 | AM41: =IF(AM40="","",VLOOKUP(AM40,'[1]All Player'!$A$2:$D$517,2,FALSE)) -> NO | AN41: - | AO41: =IF(AM40="","",VLOOKUP(AM40,'[1]All Player'!$A$2:$D$517,4,FALSE)) -> DEF | AP41: =AK41+0.01 -> 13.08 | AR41: =IF(AR40="","",VLOOKUP(AR40,'[1]All Player'!$A$2:$D$517,2,FALSE)) -> SF | AS41: - | AT41: =IF(AR40="","",VLOOKUP(AR40,'[1]All Player'!$A$2:$D$517,4,FALSE)) -> WR | AU41: =AP41+0.01 -> 13.09 | AW41: =IF(AW40="","",VLOOKUP(AW40,'[1]All Player'!$A$2:$D$517,2,FALSE)) -> ATL | AX41: - | AY41: =IF(AW40="","",VLOOKUP(AW40,'[1]All Player'!$A$2:$D$517,4,FALSE)) -> QB | AZ41: =AU41+0.01 -> 13.1 | BB41: =IF(BB40="","",VLOOKUP(BB40,'[1]All Player'!$A$2:$D$517,2,FALSE)) -> NYG | BC41: - | BD41: =IF(BB40="","",VLOOKUP(BB40,'[1]All Player'!$A$2:$D$517,4,FALSE)) -> TE | BE41: =AZ41+0.01 -> 13.11 | BG41: =IF(BG40="","",VLOOKUP(BG40,'[1]All Player'!$A$2:$D$517,2,FALSE)) -> DEN | BH41: - | BI41: =IF(BG40="","",VLOOKUP(BG40,'[1]All Player'!$A$2:$D$517,4,FALSE)) -> RB | BJ41: =BE41+0.01 -> 13.12 | BL41: =IF(BL40="","",VLOOKUP(BL40,'[1]All Player'!$A$2:$D$517,2,FALSE)) -> DEN | BM41: - | BN41: =IF(BL40="","",VLOOKUP(BL40,'[1]All Player'!$A$2:$D$517,4,FALSE)) -> WR | BO41: =BJ41+0.01 -> 13.13 | BQ41: =IF(BQ40="","",VLOOKUP(BQ40,'[1]All Player'!$A$2:$D$517,2,FALSE)) -> WAS | BR41: - | BS41: =IF(BQ40="","",VLOOKUP(BQ40,'[1]All Player'!$A$2:$D$517,4,FALSE)) -> TE | BT41: =BO41+0.01 -> 13.14 | BV41: =IF(BV40="","",VLOOKUP(BV40,'[1]All Player'!$A$2:$D$517,2,FALSE)) -> DEN | BW41: - | BX41: =IF(BV40="","",VLOOKUP(BV40,'[1]All Player'!$A$2:$D$517,4,FALSE)) -> TE | BY41: =BT41+0.01 -> 13.15 | CA41: =IF(CA40="","",VLOOKUP(CA40,'[1]All Player'!$A$2:$D$517,2,FALSE)) -> GB | CB41: - | CC41: =IF(CA40="","",VLOOKUP(CA40,'[1]All Player'!$A$2:$D$517,4,FALSE)) -> DEF | CD41: =BY41+0.01 -> 13.16 | CF41: =IF(CF40="","",VLOOKUP(CF40,'[1]All Player'!$A$2:$D$517,2,FALSE)) -> SEA | CG41: - | CH41: =IF(CF40="","",VLOOKUP(CF40,'[1]All Player'!$A$2:$D$517,4,FALSE)) -> QB | CI41: =CD41+0.01 -> 13.17 | CK41: =IF(CK40="","",VLOOKUP(CK40,'[1]All Player'!$A$2:$D$517,2,FALSE)) -> SF | CL41: - | CM41: =IF(CK40="","",VLOOKUP(CK40,'[1]All Player'!$A$2:$D$517,4,FALSE)) -> RB | CN41: =CI41+0.01 -> 13.18 | CP41: =IF(CP40="","",VLOOKUP(CP40,'[1]All Player'!$A$2:$D$517,2,FALSE)) -> LAR | CQ41: - | CR41: =IF(CP40="","",VLOOKUP(CP40,'[1]All Player'!$A$2:$D$517,4,FALSE)) -> WR | CS41: =CN41+0.01 -> 13.19 | CU41: =IF(CU40="","",VLOOKUP(CU40,'[1]All Player'!$A$2:$D$517,2,FALSE)) -> NYG | CV41: - | CW41: =IF(CU40="","",VLOOKUP(CU40,'[1]All Player'!$A$2:$D$517,4,FALSE)) -> WR | CX41: =CS41+0.01 -> 13.2
B43: 14. Runde | D43: Malachi Corley | I43: Elijah Moore | N43: Jason Myers | S43: Cairo Santos | X43: Las Vegas Raiders | AC43: Deuce Vaughn | AH43: Javon Baker | AM43: Jermaine Burton | AR43: New England Patriots | AW43: Minnesota Vikings | BB43: Jacksonville Jaguars | BG43: Cameron Dicker | BL43: Cincinnati Bengals | BQ43: Jake Elliott | BV43: Greg Zuerlein | CA43: Matt Gay | CF43: Evan Hull | CK43: Denver Broncos | CP43: Eric Gray | CU43: Raheem Blackshear
